[2022-09-12T08:48:54.093+0000] {taskinstance.py:1171} INFO - Dependencies all met for <TaskInstance: basic_cloud_scheduler_dag.hourly_cloud_calc manual__2022-09-12T08:48:50.416281+00:00 [queued]>
[2022-09-12T08:48:54.100+0000] {taskinstance.py:1171} INFO - Dependencies all met for <TaskInstance: basic_cloud_scheduler_dag.hourly_cloud_calc manual__2022-09-12T08:48:50.416281+00:00 [queued]>
[2022-09-12T08:48:54.100+0000] {taskinstance.py:1368} INFO - 
--------------------------------------------------------------------------------
[2022-09-12T08:48:54.100+0000] {taskinstance.py:1369} INFO - Starting attempt 1 of 1
[2022-09-12T08:48:54.100+0000] {taskinstance.py:1370} INFO - 
--------------------------------------------------------------------------------
[2022-09-12T08:48:54.110+0000] {taskinstance.py:1389} INFO - Executing <Task(SimpleHttpOperator): hourly_cloud_calc> on 2022-09-12 08:48:50.416281+00:00
[2022-09-12T08:48:54.113+0000] {standard_task_runner.py:52} INFO - Started process 16419 to run task
[2022-09-12T08:48:54.115+0000] {standard_task_runner.py:79} INFO - Running: ['***', 'tasks', 'run', 'basic_cloud_scheduler_dag', 'hourly_cloud_calc', 'manual__2022-09-12T08:48:50.416281+00:00', '--job-id', '4', '--raw', '--subdir', 'DAGS_FOLDER/basic_cloud_scheduler_dag.py', '--cfg-path', '/tmp/tmprw8zyf19', '--error-file', '/tmp/tmp_z56jpyt']
[2022-09-12T08:48:54.116+0000] {standard_task_runner.py:80} INFO - Job 4: Subtask hourly_cloud_calc
[2022-09-12T08:48:54.157+0000] {task_command.py:371} INFO - Running <TaskInstance: basic_cloud_scheduler_dag.hourly_cloud_calc manual__2022-09-12T08:48:50.416281+00:00 [running]> on host a73a9db5b359
[2022-09-12T08:48:54.214+0000] {taskinstance.py:1583} INFO - Exporting the following env vars:
AIRFLOW_CTX_DAG_OWNER=***
AIRFLOW_CTX_DAG_ID=basic_cloud_scheduler_dag
AIRFLOW_CTX_TASK_ID=hourly_cloud_calc
AIRFLOW_CTX_EXECUTION_DATE=2022-09-12T08:48:50.416281+00:00
AIRFLOW_CTX_TRY_NUMBER=1
AIRFLOW_CTX_DAG_RUN_ID=manual__2022-09-12T08:48:50.416281+00:00
[2022-09-12T08:48:54.215+0000] {http.py:121} INFO - Calling HTTP method
[2022-09-12T08:48:54.221+0000] {base.py:68} INFO - Using connection ID 'user_api' for task execution.
[2022-09-12T08:48:54.222+0000] {http.py:148} INFO - Sending 'GET' to url: http://r_server:8888/cloud/
[2022-09-12T08:48:54.300+0000] {http.py:161} ERROR - HTTP error: Not Found
[2022-09-12T08:48:54.300+0000] {http.py:162} ERROR - {"error":"404 - Resource Not Found"}
[2022-09-12T08:48:54.309+0000] {taskinstance.py:1902} ERROR - Task failed with exception
Traceback (most recent call last):
  File "/home/airflow/.local/lib/python3.7/site-packages/airflow/providers/http/hooks/http.py", line 159, in check_response
    response.raise_for_status()
  File "/home/airflow/.local/lib/python3.7/site-packages/requests/models.py", line 1022, in raise_for_status
    raise HTTPError(http_error_msg, response=self)
requests.exceptions.HTTPError: 404 Client Error: Not Found for url: http://r_server:8888/cloud/

During handling of the above exception, another exception occurred:

Traceback (most recent call last):
  File "/home/airflow/.local/lib/python3.7/site-packages/airflow/providers/http/operators/http.py", line 123, in execute
    response = http.run(self.endpoint, self.data, self.headers, self.extra_options)
  File "/home/airflow/.local/lib/python3.7/site-packages/airflow/providers/http/hooks/http.py", line 149, in run
    return self.run_and_check(session, prepped_request, extra_options)
  File "/home/airflow/.local/lib/python3.7/site-packages/airflow/providers/http/hooks/http.py", line 202, in run_and_check
    self.check_response(response)
  File "/home/airflow/.local/lib/python3.7/site-packages/airflow/providers/http/hooks/http.py", line 163, in check_response
    raise AirflowException(str(response.status_code) + ":" + response.reason)
airflow.exceptions.AirflowException: 404:Not Found
[2022-09-12T08:48:54.312+0000] {taskinstance.py:1412} INFO - Marking task as FAILED. dag_id=basic_cloud_scheduler_dag, task_id=hourly_cloud_calc, execution_date=20220912T084850, start_date=20220912T084854, end_date=20220912T084854
[2022-09-12T08:48:54.320+0000] {standard_task_runner.py:97} ERROR - Failed to execute job 4 for task hourly_cloud_calc (404:Not Found; 16419)
[2022-09-12T08:48:54.327+0000] {local_task_job.py:156} INFO - Task exited with return code 1
[2022-09-12T08:48:54.350+0000] {local_task_job.py:279} INFO - 0 downstream tasks scheduled from follow-on schedule check
